<?xml version="1.0"?>
<!--
  Copyright 2015 Fadri Furrer, ASL, ETH Zurich, Switzerland
  Copyright 2015 Michael Burri, ASL, ETH Zurich, Switzerland
  Copyright 2015 Mina Kamel, ASL, ETH Zurich, Switzerland
  Copyright 2015 Janosch Nikolic, ASL, ETH Zurich, Switzerland
  Copyright 2015 Markus Achtelik, ASL, ETH Zurich, Switzerland

  Licensed under the Apache License, Version 2.0 (the "License");
  you may not use this file except in compliance with the License.
  You may obtain a copy of the License at

  http://www.apache.org/licenses/LICENSE-2.0

  Unless required by applicable law or agreed to in writing, software
  distributed under the License is distributed on an "AS IS" BASIS,
  WITHOUT WARRANTIES OR CONDITIONS OF ANY KIND, either express or implied.
  See the License for the specific language governing permissions and
  limitations under the License.
-->
<robot xmlns:xacro="http://ros.org/wiki/xacro">
  <!-- Main multirotor link -->
  <xacro:macro name="multirotor_base_macro"
    params="robot_namespace mass body_width body_height mesh_file mesh_scale *inertia">
    <joint name="rover/imu_joint" type="fixed">
      <parent link="base_link"/>
      <child link="rover/imu_link"/>
      <origin rpy="0  0  0" xyz="0  0  0"/>
      <axis xyz="1  0  0"/>
      <limit effort="0.0" lower="0.0" upper="0.0" velocity="0.0"/>
    </joint>
    <joint name="front_left_steering_joint" type="revolute">
      <parent link="base_link"/>
      <child link="front_left_wheel_steering_block"/>
      <origin rpy="1.57079  0       0" xyz="1.20222  0.5      0.35515"/>
      <axis xyz="0  1  0"/>
      <limit effort="0.0" lower="-0.7727" upper="0.7727" velocity="0.0"/>
    </joint>
    <joint name="front_left_wheel_joint" type="fixed">
      <parent link="front_left_wheel_steering_block"/>
      <child link="front_left_wheel"/>
      <origin rpy="-3.09079  0       0" xyz="0      -0.00818 -0.21562"/>
      <axis xyz="0.00000000e+00   8.30000000e-04   1.00000000e+00"/>
      <limit effort="0" lower="0" upper="0" velocity="0"/>
    </joint>
    <joint name="front_right_steering_joint" type="revolute">
      <parent link="base_link"/>
      <child link="front_right_wheel_steering_block"/>
      <origin rpy="1.57079  0       0" xyz="1.20222 -0.5      0.35515"/>
      <axis xyz="0  1  0"/>
      <limit effort="0.0" lower="-0.7727" upper="0.7727" velocity="0.0"/>
    </joint>
    <joint name="front_right_wheel_joint" type="fixed">
      <parent link="front_right_wheel_steering_block"/>
      <child link="front_right_wheel"/>
      <origin rpy="-0.05079  0       0" xyz="0      -0.00818  0.21562"/>
      <axis xyz="0.00000000e+00   8.30000000e-04  -1.00000000e+00"/>
      <limit effort="0" lower="0" upper="0" velocity="0"/>
    </joint>
    <joint name="rear_left_wheel_joint" type="fixed">
      <parent link="base_link"/>
      <child link="rear_left_wheel"/>
      <origin rpy="-1.52  0    0" xyz="-0.99377  0.71562  0.34697"/>
      <axis xyz="0.00000000e+00   8.30000000e-04   1.00000000e+00"/>
      <limit effort="0" lower="0" upper="0" velocity="0"/>
    </joint>
    <joint name="rear_right_wheel_joint" type="fixed">
      <parent link="base_link"/>
      <child link="rear_right_wheel"/>
      <origin rpy="1.52  0    0" xyz="-0.99377 -0.61574  0.34189"/>
      <axis xyz="0.00000000e+00   8.30000000e-04  -1.00000000e+00"/>
      <limit effort="0" lower="0" upper="0" velocity="0"/>
    </joint>
    <link name="base_link">
      <inertial>
        <mass value="720.0"/>
        <origin rpy="0  0  0" xyz="0.1  0   0.4"/>
        <inertia ixx="140" ixy="0.0" ixz="0.0" iyy="550" iyz="0.0" izz="550"/>
      </inertial>
      <collision name="base_link_bottom">
        <origin rpy="0  0  0" xyz="0.2    0     0.335"/>
        <geometry>
          <box size="1.34 1.65746 0.06"/>
        </geometry>
      </collision>
      <collision name="cargo_bottom">
        <origin rpy="0  0  0" xyz="-1     0     0.921"/>
        <geometry>
          <box size="1.04609 1.6998 0.01"/>
        </geometry>
      </collision>
      <collision name="cargo_front">
        <origin rpy="0  0  0" xyz="-0.495  0     1.06"/>
        <geometry>
          <box size="0.05 1.69982 0.27"/>
        </geometry>
      </collision>
      <collision name="cargo_back">
        <origin rpy="0  0  0" xyz="-1.465  0     1.06"/>
        <geometry>
          <box size="0.05 1.69982 0.27"/>
        </geometry>
      </collision>
      <collision name="cargo_left">
        <origin rpy="0  0  0" xyz="-0.97     0.82491  1.06"/>
        <geometry>
          <box size="1.04609 0.05 0.27"/>
        </geometry>
      </collision>
      <collision name="cargo_right">
        <origin rpy="0  0  0" xyz="-0.97    -0.82491  1.06"/>
        <geometry>
          <box size="1.04609 0.05 0.27"/>
        </geometry>
      </collision>
      <collision name="seat">
        <origin rpy="0  0  0" xyz="0    0    0.62"/>
        <geometry>
          <box size="0.52167 1.37206 0.53369"/>
        </geometry>
      </collision>
      <collision name="mud_seat">
        <origin rpy="0  0  0" xyz="0    0    0.86"/>
        <geometry>
          <box size="0.52167 1.30 0.1"/>
        </geometry>
      </collision>
      <collision name="seat_back">
        <origin rpy="0  -0.2  0" xyz="-0.26   0     1.125"/>
        <geometry>
          <box size="0.06 1.37206 0.6"/>
        </geometry>
      </collision>
      <collision name="engine">
        <origin rpy="0  0  0" xyz="1.12  0    0.7"/>
        <geometry>
          <box size="0.58 1.3 0.8"/>
        </geometry>
      </collision>
      <collision name="rollcage_top_left">
        <origin rpy="3.14159  1.54159  3.14159" xyz="-0.02   0.76   1.936"/>
        <geometry>
          <cylinder length="0.68" radius="0.03"/>
        </geometry>
      </collision>
      <collision name="rollcage_top_right">
        <origin rpy="3.14159  1.54159  3.14159" xyz="-0.02  -0.76   1.936"/>
        <geometry>
          <cylinder length="0.68" radius="0.03"/>
        </geometry>
      </collision>
      <collision name="rollcage_top_front">
        <origin rpy="0 -1  0" xyz="0.315  0     1.93"/>
        <geometry>
          <box size="0.01299 1.54 0.10226"/>
        </geometry>
      </collision>
      <collision name="rollcage_top_back">
        <origin rpy="0  0  0" xyz="-0.41  0    1.88"/>
        <geometry>
          <box size="0.01299 1.54 0.10226"/>
        </geometry>
      </collision>
      <collision name="rollcage_front_left">
        <origin rpy="0   -0.54  0" xyz="0.602  0.755  1.45"/>
        <geometry>
          <cylinder length="1.15" radius="0.03"/>
        </geometry>
      </collision>
      <collision name="rollcage_front_right">
        <origin rpy="0   -0.54  0" xyz="0.602 -0.755  1.45"/>
        <geometry>
          <cylinder length="1.15" radius="0.03"/>
        </geometry>
      </collision>
      <collision name="rollcage_back_left">
        <origin rpy="0  0  0" xyz="-0.4    0.755  1.45"/>
        <geometry>
          <cylinder length="1.00" radius="0.03"/>
        </geometry>
      </collision>
      <collision name="rollcage_back_right">
        <origin rpy="0  0  0" xyz="-0.4   -0.755  1.45"/>
        <geometry>
          <cylinder length="1.00" radius="0.03"/>
        </geometry>
      </collision>
      <collision name="rollcage_X_1">
        <origin rpy="0.397  0     0" xyz="-0.411  0.04   1.445"/>
        <geometry>
          <box size="0.01392 1.557245 0.078"/>
        </geometry>
      </collision>
      <collision name="rollcage_X_2">
        <origin rpy="-0.397  0     0" xyz="-0.4   -0.04   1.445"/>
        <geometry>
          <box size="0.01392 1.557245 0.078"/>
        </geometry>
      </collision>
      <collision name="central_hump1_collision">
        <origin rpy="0  0  0" xyz="0.55 -0.1   0.4"/>
        <geometry>
          <box size="0.6 0.15 0.1"/>
        </geometry>
      </collision>
      <collision name="central_hump2_collision">
        <origin rpy="0  -0.5  0" xyz="0.7  -0.05  0.45"/>
        <geometry>
          <box size="0.20 0.05 0.1"/>
        </geometry>
      </collision>
      <collision name="central_hump3_collision">
        <origin rpy="0  -0.8  0" xyz="0.798 -0.125  0.478"/>
        <geometry>
          <box size="0.129 0.1 0.05"/>
        </geometry>
      </collision>
      <collision name="central_hump4_collision">
        <origin rpy="0  0  0" xyz="0.8135 -0.05    0.45"/>
        <geometry>
          <box size="0.10 0.05 0.1835"/>
        </geometry>
      </collision>
      <collision name="central_hump5_collision">
        <origin rpy="0  0  0" xyz="0.84  -0.125  0.45"/>
        <geometry>
          <box size="0.03 0.1 0.1835"/>
        </geometry>
      </collision>
      <collision name="central_hump6_collision">
        <origin rpy="0  0  0" xyz="0.82  -0.125  0.475"/>
        <geometry>
          <box size="0.03 0.1 0.05"/>
        </geometry>
      </collision>
      <visual name="visual">
        <origin rpy="0       0      -1.57079" xyz="0  0  0"/>
        <geometry>
          <mesh filename="/home/kdh/catkin_ws/src/drone_base/models/rover/meshes/polaris.dae" scale="1.0 1.0 1.0"/>
        </geometry>
      </visual>
      <visual name="cargo_visual">
        <origin rpy="0      0     -1.5707" xyz="-1      0      1.0323"/>
      </visual>
      <visual name="tailgate_visual">
        <origin rpy="0      0     -1.5707" xyz="-1.492  0     1.03"/>
      </visual>
      <visual name="front_left_brake_visual">
        <origin rpy="3.1415  0      1.5707" xyz="1.12    -0.57487  0.35516"/>
      </visual>
      <visual name="front_right_brake_visual">
        <origin rpy="3.1415  0      1.5707" xyz="1.12     0.57487  0.35516"/>
      </visual>
      <visual name="central_hump1">
        <origin rpy="0  0  0" xyz="0.55 -0.1   0.4"/>
        <geometry>
          <box size="0.6 0.15 0.1"/>
        </geometry>
      </visual>
      <visual name="central_hump2">
        <origin rpy="0  -0.5  0" xyz="0.7  -0.05  0.45"/>
        <geometry>
          <box size="0.20 0.05 0.1"/>
        </geometry>
      </visual>
      <visual name="central_hump3">
        <origin rpy="0  -0.8  0" xyz="0.798 -0.125  0.478"/>
        <geometry>
          <box size="0.129 0.1 0.05"/>
        </geometry>
      </visual>
      <visual name="central_hump4">
        <origin rpy="0  0  0" xyz="0.8135 -0.05    0.45"/>
        <geometry>
          <box size="0.10 0.05 0.1835"/>
        </geometry>
      </visual>
      <visual name="central_hump5">
        <origin rpy="0  0  0" xyz="0.84  -0.125  0.45"/>
        <geometry>
          <box size="0.03 0.1 0.1835"/>
        </geometry>
      </visual>
      <visual name="central_hump6">
        <origin rpy="0  0  0" xyz="0.82  -0.125  0.475"/>
        <geometry>
          <box size="0.03 0.1 0.05"/>
        </geometry>
      </visual>
    </link>
    <link name="rover/imu_link">
      <inertial>
        <mass value="0.015"/>
        <origin rpy="0  0  0" xyz="0  0  0"/>
        <inertia ixx="1e-05" ixy="0" ixz="0" iyy="1e-05" iyz="0" izz="1e-05"/>
      </inertial>
    </link>
    <link name="front_left_wheel">
      <inertial>
        <mass value="12"/>
        <origin rpy="0  0  0" xyz="0  0  0"/>
        <inertia ixx="0.5" ixy="0.0" ixz="0.0" iyy="0.5" iyz="0.0" izz="1.0"/>
      </inertial>
      <collision name="collision">
        <origin rpy="0  0  0" xyz="0  0  0"/>
        <geometry>
          <cylinder length="0.2794" radius="0.3175"/>
        </geometry>
      </collision>
      <visual name="visual">
        <origin rpy="3.14159  1.57079  0" xyz="0  0  0"/>
      </visual>
    </link>
    <link name="front_right_wheel">
      <inertial>
        <mass value="12"/>
        <origin rpy="0  0  0" xyz="0  0  0"/>
        <inertia ixx="0.5" ixy="0.0" ixz="0.0" iyy="0.5" iyz="0.0" izz="1.0"/>
      </inertial>
      <collision name="collision">
        <origin rpy="0  0  0" xyz="0  0  0"/>
        <geometry>
          <cylinder length="0.2794" radius="0.3175"/>
        </geometry>
      </collision>
      <visual name="visual">
        <origin rpy="0      -1.57079  0" xyz="0  0  0"/>
      </visual>
    </link>
    <link name="rear_left_wheel">
      <inertial>
        <mass value="12"/>
        <origin rpy="0  0  0" xyz="0  0  0"/>
        <inertia ixx="0.5" ixy="0.0" ixz="0.0" iyy="0.5" iyz="0.0" izz="1.0"/>
      </inertial>
      <collision name="collision">
        <origin rpy="0  0  0" xyz="0  0  0"/>
        <geometry>
          <cylinder length="0.2794" radius="0.3175"/>
        </geometry>
      </collision>
      <visual name="visual">
        <origin rpy="0      -1.57079  0" xyz="0  0  0"/>>
      </visual>
    </link>
    <link name="rear_right_wheel">
      <inertial>
        <mass value="12"/>
        <origin rpy="0  0  0" xyz="0  0  0"/>
        <inertia ixx="0.5" ixy="0.0" ixz="0.0" iyy="0.5" iyz="0.0" izz="1.0"/>
      </inertial>
      <collision name="collision">
        <origin rpy="0  0  0" xyz="0   0   0.1"/>
        <geometry>
          <cylinder length="0.2794" radius="0.3175"/>
        </geometry>
      </collision>
      <visual name="visual">
        <origin rpy="0      -1.57079  0" xyz="0   0   0.1"/>
      </visual>
    </link>
    <link name="front_right_wheel_steering_block">
      <inertial>
        <mass value="1"/>
        <origin rpy="0  0  0" xyz="0  0  0"/>
        <inertia ixx="0.01" ixy="0.0" ixz="0.0" iyy="0.01" iyz="0.0" izz="0.01"/>
      </inertial>
      <collision name="collision">
        <origin rpy="0  0  0" xyz="0  0  0"/>
        <geometry>
          <cylinder length="0.01" radius="0.05"/>
        </geometry>
      </collision>
    </link>
    <link name="front_left_wheel_steering_block">
      <inertial>
        <mass value="1"/>
        <origin rpy="0  0  0" xyz="0  0  0"/>
        <inertia ixx="0.01" ixy="0.0" ixz="0.0" iyy="0.01" iyz="0.0" izz="0.01"/>
      </inertial>
      <collision name="collision">
        <origin rpy="0  0  0" xyz="0  0  0"/>
        <geometry>
          <cylinder length="0.01" radius="0.05"/>
        </geometry>
      </collision>
    </link>
    

    <!-- attach multirotor_base_plugin to the base_link -->
    <gazebo>
      <!--this model is affected by wind  -->
      <enable_wind>true</enable_wind>
      <plugin filename="libgazebo_multirotor_base_plugin.so" name="rosbag">
        <robotNamespace>${robot_namespace}</robotNamespace>
        <linkName>base_link</linkName>
        <rotorVelocitySlowdownSim>${rotor_velocity_slowdown_sim}</rotorVelocitySlowdownSim>
      </plugin>
    </gazebo>
  </xacro:macro>

</robot>
